Traceback (most recent call last):
  File "/home/haoran/.local/lib/python3.8/site-packages/wandb/sdk/wandb_config.py", line 162, in __getattr__
    return self.__getitem__(key)
  File "/home/haoran/.local/lib/python3.8/site-packages/wandb/sdk/wandb_config.py", line 130, in __getitem__
    return self._items[key]
KeyError: 'batch_size'
The above exception was the direct cause of the following exception:
Traceback (most recent call last):
  File "train_classification.py", line 156, in train
    dataloader = get_Dataloader(config.batch_size)
  File "/home/haoran/.local/lib/python3.8/site-packages/wandb/sdk/wandb_config.py", line 164, in __getattr__
    raise AttributeError(
AttributeError: <class 'wandb.sdk.wandb_config.Config'> object has no attribute 'batch_size'